Workbook

Sheet 00_README
A1: Nucleus HRMS — Demo Dataset v1.0
A3: Version | B3: v1.1, 15 September 2026. Extends v1.0 with 33 sheets and corrects four data defects. Read 70_Change_Log_v1_1 first, then 69_Coverage_Matrix. Load order for the added sheets is in the change log note. Every formula from v1.0 is unchanged and recalculates identically.
A4: Purpose | B4: Reference data for populating a Nucleus demo tenant. Every record is engineered so that one or more of the 26 client demo points can be shown live, end to end.
A5: Demo client | B5: Vindhya Precision Industries Pvt Ltd — a fictional multi-state manufacturer. Two legal entities, five sites, four states, 68 workers across nine worker classes.
A6: Demo period | B6: Attendance and transactions are dated 01–15 September 2026. Payroll cycle is September 2026. Set the demo tenant clock to 15 September 2026 so open items sit in the right state.
A8: HOW TO USE THIS FILE
A9: 1 | B9: Load sheets in the numbered order. 02–19 are master and configuration data and must exist before any transaction sheet will import.
A10: 2 | B10: Enter the data exactly as given. The values are not arbitrary — thresholds, times, dates and amounts are chosen so the expected results in sheet 21 are reproduced by the product.
A11: 3 | B11: After loading, run the attendance computation for 01–15 September and reconcile against sheet 21 (21_Expected_Attendance). Any row where the product disagrees with the expected status is a defect to fix before the demo, not a data error.
A12: 4 | B12: Sheet 01_Scenario_Map is the demo script. It names, for each of the 26 client points, the exact records to open on screen and what the client should see.
A14: LEGEND — how to read the sheets
A15: Codes ending in a number | B15: Primary keys. Use these exact values; every other sheet references them.
A16: Demo_Point column | B16: Names the client requirement that the row exists to prove. Blank means the row is background data providing realistic volume.
A17: Grey banded rows | B17: Alternate-row shading only. No meaning.
A18: Amber cells | B18: A value that must be entered exactly as given, because a computed result depends on it.
A19: Blank cells | B19: Deliberately empty — either not applicable to that worker class, or a field the product is expected to derive.
A20: Formulas | B20: Sheets 13, 21 and 24 carry formulas that derive values from the configuration sheets. They are there so the dataset checks itself — if you change a threshold in 08, the expected status in 21 updates.
A22: WHAT IS DELIBERATELY NOT HERE
A23: Bank account numbers | B23: Only last four digits are given. Use the product's own test account generator.
A24: Aadhaar, PAN, UAN | B24: Format-valid dummy values only, flagged as such. Never demo with real identifiers.
A25: Photographs and documents | B25: Attach any placeholder; none are supplied.
A27: COVERAGE | B27: All 26 demo points are covered. See 01_Scenario_Map for the record-level mapping.

Sheet 01_Scenario_Map
A1: Demo point | B1: Requirement | C1: Client status | D1: Sheets to load | E1: Records to open | F1: What the client should see | G1: Also load (added in v1.1)
A2: 1 | B2: Multi-punch day, 19h20m across midnight, separate dinner-break report, OT 7h20m | C2: WIP | D2: 20_Punch_Events, 21_Expected_Attendance | E2: E1018 Ravi Kulkarni, 08 Sep 2026 | F2: Two segments (08:00–20:30, 21:15–03:20). Gross 19h20m, dinner break 45m listed separately, OT 7h20m against the 12h shift. Attendance date stays 08 Sep, not split across two days. | G2: 49_Break_Register, 43_Roles_and_Data_Scope, 44_Demo_Users, 52_Shift_Roster
A3: 1 | B3: Team history for a date range, from the team calendar | C3: WIP | D3: 21_Expected_Attendance | E3: Manager E1017 Nikhil Iyer, 01–15 Sep | F3: Filter by manager and date range; export the per-day attendance, OT, late and gate-pass columns. | G3: 49_Break_Register, 43_Roles_and_Data_Scope, 44_Demo_Users, 52_Shift_Roster
A4: 2 | B4: Contractual employees have no rest days and are paid daily wages | C4: WIP | D4: 06_Worker_Classes, 12_Employees, 21_Expected_Attendance | E4: WC-CONT; E1032 Shivanna Muniyappa, 06 and 13 Sep | F4: Sundays appear as Working, not Weekly Off. Wage type Daily on the employee record. | G4: 38_Employment_Categories, 47_Pay_Components, 55_Payroll_Register
A5: 3 | B5: Third-party group: employees have rest days, helpers do not | C5: WIP | D5: 06_Worker_Classes, 12_Employees, 21_Expected_Attendance | E5: E1034 Imran Shaikh (WC-3PE) vs E1036 Lakshmi Rao (WC-3PH), 06 Sep | F5: Same vendor VN-01, same site, same shift. Sunday is Weekly Off for one and Working for the other. | G5: 38_Employment_Categories, 45_Vendors_Contractors, 46_Contractor_Invoices
A6: 4 | B6: Overtime only on rest days or holidays for some employees | C6: WIP | D6: 06_Worker_Classes, 21_Expected_Attendance | E6: E1034 Imran Shaikh, 04 Sep vs 06 Sep | F6: Weekday OT computes to zero despite a 12h+ span. Rest-day working pays the whole span as OT. | G6: 38_Employment_Categories, 55_Payroll_Register
A7: 5 | B7: Early return from leave — mark present, re-credit balance, three-level approval | C7: Done | D7: 18_Leave_Requests, 17_Leave_Ledger | E7: LV-2026-0774, E1043 Neha Mishra | F7: Applied 10 days, returned after 6. Ledger shows the original debit and a reversal credit of the unused days. Approval trail shows Supervisor, then HOD, then HR Head, with an HR edit logged. | G7: 50_Attendance_Regularisation, 53_Leave_Balance_AsOn, 64_Approval_Workflows
A8: 6 | B8: Comp-off lapses 60 days from the credit date | C8: WIP | D8: 19_CompOff_Ledger | E8: CO-2026-0231 (E1028) and CO-2026-0288 (E1028) | F8: Two credits on separate clocks. The July credit lapses 10 Sep; the 06 Sep credit runs to 05 Nov. Show that a single balance-level expiry cannot express this. | G8: 53_Leave_Balance_AsOn — the ledger now reconciles to the comp-off register
A9: 7 | B9: Auto leave credit — bands, accrual, joiner proration, caps, encashment, trainees | C9: WIP | D9: 14_Leave_Types, 15_Leave_Accrual_Policy, 16_Leave_Proration, 17_Leave_Ledger | E9: E1004 (AGM band, 18 EL), E1019 (standard, 1.5 EL/month), E1067 Ankita Bhargava (6 months on 16 Sep, 9 EL), E1060 (April joiner, 4 CL/SL), E1030/E1031 (GET/DET) | F9: Walk the ladder from policy to individual balance. Then attempt a CL+EL combined application and show it blocked by the exclusion rule, and an 11th EL day in one month blocked by the monthly cap. | G9: 39_Leave_Schemes, 40_Leave_Rules_Matrix, 53_Leave_Balance_AsOn, 54_Year_End_Leave_Preview
A10: 8 | B10: HO-generated salary, plant attendance, plant users cannot see rate | C10: Done | D10: 12_Employees, 13_Salary_Structure | E10: E1056 Anand Krishnan — location LOC-CHN, payroll group HO | F10: Sign in as the Chennai plant HR user: attendance visible and editable, every compensation field blank. Sign in as E1007 Deepak Sarangi (payroll): the same record shows full salary. | G10: 43_Roles_and_Data_Scope, 44_Demo_Users, 55_Payroll_Register
A11: 9 | B11: Loan policy — one at a time, guarantors, 4x and 6x basic, guarantor lock, override | C11: Done | D11: 24_Loans, 25_Loan_Guarantors | E11: LN-2026-0041, LN-2026-0009, LN-APP-2026-0014, LN-2026-0012 | F11: E1044 has an active loan at 4x basic. His guarantors E1040 and E1041 are now blocked — show E1041's application rejected with the reason. E1056 qualifies at 6x on 8 years' service. E1050's closed loan released his guarantors. E1022 carries a director-approved special-terms sanction. | G11: 64_Approval_Workflows
A12: 10 | B12: Overtime generated and paid after salary, not with it | C12: Done | D12: 23_Overtime_Register, 26_Payroll_Runs | E12: PR-2026-09-01 and PR-2026-09-02 | F12: Two runs against September. The regular run releases on 30 Sep; the off-cycle OT run on 07 Oct, with its own bank file and its own GL journal line. | G12: 55_Payroll_Register, 56_GL_Journal, 57_Bank_File
A13: 11 | B13: Gate pass — 4 hours a month, maximum two, added to work hours | C13: Done | D13: 22_Gate_Pass, 21_Expected_Attendance | E13: GP-2026-0141, GP-2026-0155, GP-2026-0163 (E1023) | F13: Two approved passes of 2h each. Both dates show the gap as a break and the same minutes credited back, so net hours are unaffected. The third request is rejected on the monthly ceiling. | G13: 49_Break_Register, 67_Reports_Register
... A15: 13 | B15: Auto shift capture from the in-punch | C15: Done | D15: 07_Shifts, 21_Expected_Attendance | E15: E1020 Arjun Bhat, 04 and 11 Sep | F15: Assigned SH-A, punched inside the SH-B window. Shift_Applied differs from Shift_Assigned and the 12h threshold is applied against the inferred shift. | G15: 52_Shift_Roster, 51_Attendance_Exceptions
A16: 14 | B16: Link the ERP employee master by API | C16: Done | D16: 36_ERP_Inbound_Master | E16: Batch ERP-SYNC-2026-09-14, six rows | F16: Three clean upserts, one field-ownership conflict held for review, one unmatched employee code, one duplicate payload rejected on hash. Show the ownership map deciding who wins.
A17: 15 | B17: Account posting to ERP | C17: Done | D17: 35_GL_Mapping, 26_Payroll_Runs | E17: September journal, both runs | F17: Every component mapped to an account and cost centre. Show the run blocked when a mapping is missing, then the balanced journal and the reconciliation to the bank file total. | G17: 56_GL_Journal, 57_Bank_File, 35_GL_Mapping — four accounts added so the journal balances
A18: 16 | B18: Full and final on the last working day, with no-dues clearance | C18: WIP | D18: 27_Exit_Clearance | E18: E1068 Dinesh Vaidya (LWD 30 Sep), E1042 Swapnil Kadam (LWD 18 Sep) | F18: Nine checklist items with named owners, four blocking. E1042 has two open blocking items so F&F is held; E1068 is fully cleared and settles on the last working day. | G18: 58_FnF_Settlement, 33_Assets recovery value, 57_Bank_File
A19: 17 | B19: Statutory compliance, Factory Act forms and returns | C19: Done | D19: 28_Statutory_Calendar, 29_Statutory_Forms | E19: Sep–Nov obligations across four states | F19: PT differs by state on the same run. Show the register set for a Karnataka factory against Tamil Nadu. | G19: 48_PT_Slabs, 62_Documents, 45_Vendors_Contractors
A20: 18 | B20: Star employees | C20: Done | D20: 30_Recognition_Referral | E20: RC-2026-Q2-004, RC-2026-Q2-007 | F20: Programme, citation, period and the award component flowing to payroll as an earning.
A21: 19 | B21: Referral process and awards | C21: Done | D21: 30_Recognition_Referral | E21: RF-2026-0021 (part paid), RF-2026-0026 (balance due on confirmation) | F21: Referral tracked from candidate through to a payroll payout in a named run. | G21: 59_Candidates_and_Offers, 60_Confirmations
A22: 20 | B22: Announcements — birthday, star employee, new joiner, referral, management message | C22: Done | D22: 31_Announcements | E22: AN-2026-0088 through AN-2026-0094 | F22: Auto-generated from events, with audience rules and channel selection including WhatsApp.
A23: 21 | B23: Appointment and other HR letters | C23: Done | D23: 32_Letter_Templates | E23: TPL-APPT-02 issued to E1066, TPL-CONF-01 issued to E1058 | F23: Template version retained against the issued letter, so a reprint two years later is provable.
A24: 22 | B24: Organisation chart, department-wise hierarchy | C24: Done | D24: 04_Org_Units, 12_Employees | E24: OU-100 down to OU-180, three levels | F24: Drill the chart, then filter headcount by org unit and location.
A25: 23 | B25: Induction training at joining, and asset | C25: Done | D25: 33_Assets, 34_Induction_Learning | E25: E1066 Abhinav Rastogi, joined 01 Sep | F25: Induction path assigned on joining, three assets allocated, and the same assets appearing as blocking clearance items at exit. | G25: 60_Confirmations, 61_Preboarding_Chain, 62_Documents
A26: 24 | B26: Recruitment — position code for replacement | C26: Done | D26: 11_Positions, 37_Requisitions | E26: REQ-2026-0037 against vacated POS-2214; REQ-2026-0041 as an addition | F26: The replacement consumes no fresh sanction. The addition is blocked because Machining is at sanctioned strength. | G26: 59_Candidates_and_Offers, 61_Preboarding_Chain
A27: 25 | B27: Approved manpower, department wise | C27: Done | D27: 10_Sanctioned_Manpower | E27: OU-111 Machining at Peenya — 24 sanctioned, 24 filled | F27: Sanctioned against actual against open requisitions, by department, designation and location. | G27: 59_Candidates_and_Offers
A28: 26 | B28: Joining form under the Factory Act, Form F | C28: WIP | D28: 29_Statutory_Forms, 34_Induction_Learning | E28: FRM-F-2026-0112 for E1066 | F28: Generated inside the joining chain, not chased afterwards. Owner for this item is to be assigned. | G28: 61_Preboarding_Chain
A30: This sheet is the demo script. Run the points in the order your client raised them, not in numeric order.

Sheet 02_Legal_Entities
A1: Entity code | B1: Registered name | C1: CIN / LLPIN | D1: Registered office | E1: PAN | F1: PF / Labour code | G1: GSTIN | H1: Financial year | I1: Status
A2: LE-01 | B2: Vindhya Precision Industries Pvt Ltd | C2: U29253KA2011PTC058411 | D2: Bengaluru, Karnataka | E2: AAACV4471K | F2: KA/BLR/0045512 | G2: 29AAACV4471K1ZP | H2: Apr-Mar | I2: Active
A3: LE-02 | B3: Vindhya Components Pvt Ltd | C3: U29309TG2016PTC112904 | D3: Hyderabad, Telangana | E3: AAECV8820M | F3: TS/HYD/0021877 | G3: 36AAECV8820M1ZR | H3: Apr-Mar | I3: Active

Sheet 03_Locations
A1: Location code | B1: Location name | C1: Entity | D1: City | E1: State | F1: State code | G1: Establishment type | H1: PIN | I1: Factory licence | J1: PT slab set | K1: LWF set | L1: Payroll group | M1: Factory Act applies
A2: LOC-BLR | B2: Bengaluru Corporate Office | C2: LE-01 | D2: Bengaluru | E2: Karnataka | F2: KA | G2: Office | H2: 560001 | I2: Not applicable | J2: KA-PT-Slab-2026 | K2: KA-LWF | L2: HO | M2: N
A3: LOC-PLA | B3: Peenya Works | C3: LE-01 | D3: Bengaluru | E3: Karnataka | F3: KA | G3: Factory | H3: 560058 | I3: KA/FAC/2013/00891 | J3: KA-PT-Slab-2026 | K3: KA-LWF | L3: PLANT-BLR | M3: Y
A4: LOC-PUN | B4: Chakan Works | C4: LE-01 | D4: Pune | E4: Maharashtra | F4: MH | G4: Factory | H4: 410501 | I4: MH/FAC/2015/03327 | J4: MH-PT-Slab-2026 | K4: MH-LWF | L4: PLANT-PUN | M4: Y
A5: LOC-HYD | B5: Medchal Works | C5: LE-02 | D5: Hyderabad | E5: Telangana | F5: TS | G5: Factory | H5: 501401 | I5: TS/FAC/2016/01142 | J5: TS-PT-Slab-2026 | K5: TS-LWF | L5: PLANT-HYD | M5: Y
A6: LOC-CHN | B6: Oragadam Works | C6: LE-02 | D6: Chennai | E6: Tamil Nadu | F6: TN | G6: Factory | H6: 602105 | I6: TN/FAC/2015/02218 | J6: TN-PT-Slab-2026 | K6: TN-LWF | L6: PLANT-CHN | M6: Y

Sheet 04_Org_Units
A1: Org unit code | B1: Org unit name | C1: Parent | D1: Level | E1: Type | F1: Primary location | G1: Cost centre
A2: OU-100 | B2: Executive Office | D2: 1 | E2: Function | F2: LOC-BLR | G2: CC-1000
A3: OU-110 | B3: Manufacturing | C3: OU-100 | D3: 2 | E3: Function | G3: CC-2000
A4: OU-111 | B4: Machining | C4: OU-110 | D4: 3 | E4: Sub-function | G4: CC-2100
A5: OU-112 | B5: Assembly | C5: OU-110 | D5: 3 | E5: Sub-function | G5: CC-2200
A6: OU-113 | B6: Quality Assurance | C6: OU-110 | D6: 3 | E6: Sub-function | G6: CC-2300
A7: OU-114 | B7: Maintenance | C7: OU-110 | D7: 3 | E7: Sub-function | G7: CC-2400
A8: OU-120 | B8: Supply Chain | C8: OU-100 | D8: 2 | E8: Function | G8: CC-3000
A9: OU-121 | B9: Stores | C9: OU-120 | D9: 3 | E9: Sub-function | G9: CC-3100
A10: OU-122 | B10: Logistics | C10: OU-120 | D10: 3 | E10: Sub-function | G10: CC-3200
A11: OU-130 | B11: Engineering | C11: OU-100 | D11: 2 | E11: Function | G11: CC-4000
A12: OU-140 | B12: Sales & Marketing | C12: OU-100 | D12: 2 | E12: Function | F12: LOC-BLR | G12: CC-5000
A13: OU-150 | B13: Finance & Accounts | C13: OU-100 | D13: 2 | E13: Function | F13: LOC-BLR | G13: CC-6000
A14: OU-160 | B14: Human Resources | C14: OU-100 | D14: 2 | E14: Function | G14: CC-6500
A15: OU-170 | B15: Information Technology | C15: OU-100 | D15: 2 | E15: Function | F15: LOC-BLR | G15: CC-7000
A16: OU-180 | B16: Environment, Health & Safety | C16: OU-110 | D16: 3 | E16: Sub-function | G16: CC-2500

Sheet 05_Designations
A1: Designation code | B1: Title | C1: Band | D1: Exempt from grace deduction | E1: Leave band | F1: Overtime default | G1: Notice period (days) | H1: Grade rank | I1: Default leave scheme | J1: Rule the rank serves
A2: DES-01 | B2: Managing Director | C2: E | D2: Y | E2: AGM_AND_ABOVE | F2: None | G2: 90 | H2: 100 | I2: LS-AGM | J2: AGM and above — 18 EL / 6 CL / 6 SL on 1 Jan (LP-01 to LP-03); also grace-exempt
A3: DES-02 | B3: Vice President | C3: E | D3: Y | E3: AGM_AND_ABOVE | F3: None | G3: 90 | H3: 90 | I3: LS-AGM | J3: AGM and above — 18 EL / 6 CL / 6 SL on 1 Jan (LP-01 to LP-03); also grace-exempt
A4: DES-03 | B4: General Manager | C4: D | D4: Y | E4: AGM_AND_ABOVE | F4: None | G4: 90 | H4: 80 | I4: LS-AGM | J4: AGM and above — 18 EL / 6 CL / 6 SL on 1 Jan (LP-01 to LP-03); also grace-exempt
A5: DES-04 | B5: Assistant General Manager | C5: D | D5: Y | E5: AGM_AND_ABOVE | F5: None | G5: 60 | H5: 70 | I5: LS-AGM | J5: AGM and above — 18 EL / 6 CL / 6 SL on 1 Jan (LP-01 to LP-03); also grace-exempt
A6: DES-05 | B6: Senior Manager | C6: C | D6: Y | E6: STANDARD | F6: None | G6: 60 | H6: 60 | I6: LS-STD | J6: Assistant Manager and above — exempt from the late-mark deduction
A7: DES-06 | B7: Manager | C7: C | D7: Y | E7: STANDARD | F7: None | G7: 60 | H7: 55 | I7: LS-STD | J7: Assistant Manager and above — exempt from the late-mark deduction
A8: DES-07 | B8: Assistant Manager | C8: C | D8: Y | E8: STANDARD | F8: None | G8: 30 | H8: 50 | I8: LS-STD | J8: Assistant Manager and above — exempt from the late-mark deduction
A9: DES-08 | B9: Senior Engineer | C9: B | D9: N | E9: STANDARD | F9: All | G9: 30 | H9: 40 | I9: LS-STD
A10: DES-09 | B10: Engineer | C10: B | D10: N | E10: STANDARD | F10: All | G10: 30 | H10: 35 | I10: LS-STD
A11: DES-10 | B11: Senior Officer | C11: B | D11: N | E11: STANDARD | F11: All | G11: 30 | H11: 34 | I11: LS-STD
A12: DES-11 | B12: Officer | C12: A | D12: N | E12: STANDARD | F12: All | G12: 30 | H12: 30 | I12: LS-STD
A13: DES-12 | B13: Senior Operator | C13: A | D13: N | E13: STANDARD | F13: All | G13: 30 | H13: 25 | I13: LS-STD
A14: DES-13 | B14: Operator | C14: A | D14: N | E14: STANDARD | F14: All | G14: 30 | H14: 20 | I14: LS-STD
A15: DES-14 | B15: Technician | C15: A | D15: N | E15: STANDARD | F15: All | G15: 30 | H15: 20 | I15: LS-STD
A16: DES-15 | B16: Graduate Engineer Trainee | C16: T | D16: N | E16: TRAINEE_GET | F16: None | G16: 15 | H16: 15 | I16: LS-TRN
A17: DES-16 | B17: Diploma Engineer Trainee | C17: T | D17: N | E17: TRAINEE_DET | F17: None | G17: 15 | H17: 14 | I17: LS-TRN
A18: DES-17 | B18: Helper | C18: H | D18: N | E18: NOT_ELIGIBLE | F18: RestDayHolidayOnly | G18: 7 | H18: 5 | I18: LS-NONE
A19: DES-18 | B19: Contract Operator | C19: H | D19: N | E19: NOT_ELIGIBLE | F19: All | G19: 7 | H19: 5 | I19: LS-NONE
A20: DES-19 | B20: Apprentice | C20: T | D20: N | E20: NOT_ELIGIBLE | F20: None | G20: 7 | H20: 10 | I20: LS-NONE
A21: DES-20 | B21: Retainer Consultant | C21: C | D21: Y | E21: NOT_ELIGIBLE | F21: None | G21: 30 | H21: 50 | I21: LS-NONE | J21: Assistant Manager and above — exempt from the late-mark deduction
A23: Exempt from grace deduction is Y for Assistant Manager and above, per client rule. Leave band drives the accrual policy in sheet 15. ADDED v1.1: Grade rank is the single numeric ladder every "and above" rule must compare. AGM and above is rank >= 70; Assistant Manager and above is rank >= 50. No rule may match a designation name.

Sheet 06_Worker_Classes
A1: Class code | B1: Label | C1: Has rest days | D1: Rest day pattern | E1: Wage type | F1: Overtime eligibility | G1: Leave eligible | H1: Statutory set | I1: Obligation | J1: Demo point
A2: WC-PERM | B2: Permanent | C2: Y | D2: Sunday weekly off | E2: Monthly | F2: All | G2: Y | H2: PF+ESI+PT+LWF+Gratuity | I2: Direct
A3: WC-FTC | B3: Fixed Term Contract | C3: Y | D3: Sunday weekly off | E3: Monthly | F3: All | G3: Y | H3: PF+ESI+PT+LWF+Gratuity (FTC treatment) | I3: Direct
A4: WC-TRN | B4: Trainee | C4: Y | D4: Sunday weekly off | E4: Monthly | F4: None | G4: Y (CL only, per band) | H4: PF+ESI+PT | I4: Direct | J4: Point 7
A5: WC-APP | B5: Apprentice | C5: Y | D5: Sunday weekly off | E5: Stipend | F5: None | G5: N | H5: Apprentices Act — no PF/ESI | I5: Direct
A6: WC-CONT | B6: Contractual — daily wage | C6: N | D6: No rest day | E6: Daily | F6: All | G6: N | H6: PF+ESI+PT | I6: Direct | J6: Point 2
A7: WC-3PE | B7: Third-Party Employee | C7: Y | D7: Sunday weekly off | E7: Monthly | F7: RestDayHolidayOnly | G7: N | H7: Contractor's PF/ESI — verification held | I7: Principal Employer | J7: Points 3, 4
A8: WC-3PH | B8: Third-Party Helper | C8: N | D8: No rest day | E8: Daily | F8: RestDayHolidayOnly | G8: N | H8: Contractor's PF/ESI — verification held | I8: Principal Employer | J8: Point 3
A9: WC-CONS | B9: Retainer Consultant | C9: N | D9: Not applicable | E9: Retainer | F9: None | G9: N | H9: TDS 194J only | I9: Not applicable
A10: WC-GIG | B10: Gig / Platform Worker | C10: N | D10: Not applicable | E10: Per engagement | F10: None | G10: N | H10: Social Security Code — aggregator contribution | I10: Aggregator
A12: Worker class carries time and pay policy, not just statutory applicability. Every attribute here is overridable on the individual assignment with a reason.

Sheet 07_Shifts
A1: Shift code | B1: Shift name | C1: Shift group | D1: Start | E1: End | F1: Duration (min) | G1: Break — recorded, paid (min) | H1: Break — deducted (min) | I1: Inference window — earliest in | J1: Inference window — latest in | K1: Crosses midnight | L1: Half day if net below (min) | M1: Absent if net below (min) | N1: OT starts after (min) | O1: Auto detect enabled | P1: Thresholds source
A2: SH-A | B2: A Shift — Day 12h | C2: PLANT12 | D2: 08:00 | E2: 20:00 | F2: 720 | G2: 60 | H2: 0 | I2: 06:30 | J2: 09:29 | K2: N | L2: 690 | M2: 390 | N2: 720 | O2: Y | P2: Mirrors 08_Attendance_Rules for this shift length. F-SHF-01 requires the thresholds to live on the shift, not in code.
A3: SH-B | B3: B Shift — Night 12h | C3: PLANT12 | D3: 20:00 | E3: 08:00 | F3: 720 | G3: 60 | H3: 0 | I3: 19:00 | J3: 22:29 | K3: Y | L3: 690 | M3: 390 | N3: 720 | O3: Y | P3: Mirrors 08_Attendance_Rules for this shift length. F-SHF-01 requires the thresholds to live on the shift, not in code.
A4: SH-C | B4: C Shift — Early 10h | C4: PLANT10 | D4: 07:00 | E4: 17:00 | F4: 600 | G4: 45 | H4: 0 | I4: 05:30 | J4: 07:59 | K4: N | L4: 570 | M4: 360 | N4: 600 | O4: Y | P4: Mirrors 08_Attendance_Rules for this shift length. F-SHF-01 requires the thresholds to live on the shift, not in code.
A5: SH-D | B5: D Shift — Late 10h | C5: PLANT10 | D5: 17:00 | E5: 03:00 | F5: 600 | G5: 45 | H5: 0 | I5: 16:00 | J5: 18:29 | K5: Y | L5: 570 | M5: 360 | N5: 600 | O5: Y | P5: Mirrors 08_Attendance_Rules for this shift length. F-SHF-01 requires the thresholds to live on the shift, not in code.
A6: SH-E | B6: General Shift 9h | C6: STAFF9 | D6: 09:00 | E6: 18:00 | F6: 540 | G6: 45 | H6: 0 | I6: 07:30 | J6: 11:00 | K6: N | L6: 510 | M6: 300 | N6: 540 | O6: Y | P6: Mirrors 08_Attendance_Rules for this shift length. F-SHF-01 requires the thresholds to live on the shift, not in code.
A7: SH-F | B7: Office Shift 8h | C7: OFFICE8 | D7: 09:30 | E7: 17:30 | F7: 480 | G7: 30 | H7: 0 | I7: 08:00 | J7: 11:30 | K7: N | L7: 450 | M7: 270 | N7: 480 | O7: N | P7: Mirrors 08_Attendance_Rules for this shift length. F-SHF-01 requires the thresholds to live on the shift, not in code.
A9: Breaks are recorded and reported but NOT deducted for this client — see sheet 21. Inference windows do not overlap inside a shift group. An in-punch inside another shift's window within the same group causes that shift to be adopted for the day (demo point 13). ADDED v1.1: half-day, absent and OT thresholds now sit on the shift itself, as F-SHF-01 requires. They are the same numbers as 08_Attendance_Rules — if the two ever disagree, the shift master wins and 08 is the audit copy. SH-F is office staff and auto-detection is off for it.

Sheet 08_Attendance_Rules
A1: Shift hours | B1: Half day if net below (min) | C1: Absent if net below (min) | D1: Grace in (min) | E1: Grace out (min) | F1: Late instances allowed per month | G1: Long night finishes after | H1: Next-day relief until | I1: Stated as
A2: 12 | B2: 690 | C2: 390 | D2: 15 | E2: 15 | F2: 3 | G2: 03:00 | H2: 09:30 | I2: 11:30 net for half day, 6:30 for absent
A3: 10 | B3: 570 | C3: 360 | D3: 15 | E3: 15 | F3: 3 | G3: 03:00 | H3: 09:30 | I3: 9:30 net for half day, 6:00 for absent
A4: 9 | B4: 510 | C4: 300 | D4: 15 | E4: 15 | F4: 3 | G4: 03:00 | H4: 09:30 | I4: 8:30 net for half day, 5:00 for absent
A5: 8 | B5: 450 | C5: 270 | D5: 15 | E5: 15 | F5: 3 | G5: 03:00 | H5: 09:30 | I5: 7:30 net for half day, 4:30 for absent
A7: These four rows are the client's stated rule. Sheet 21 reads them by INDEX/MATCH, so changing a threshold here updates every expected status. Overtime basis for this client is the GROSS span, not net hours — see 21_Expected_Attendance.

Sheet 09_Holiday_Calendar
A1: Date | B1: Holiday | C1: Applicable locations | D1: Type
A2: 2026-01-01 | B2: New Year's Day | C2: LOC-BLR,LOC-PUN,LOC-HYD,LOC-CHN | D2: Festival
A3: 2026-01-14 | B3: Makara Sankranti / Pongal | C3: LOC-BLR,LOC-HYD,LOC-CHN | D3: Festival
A4: 2026-01-26 | B4: Republic Day | C4: ALL | D4: National
A5: 2026-03-04 | B5: Holi | C5: LOC-PUN | D5: Festival
A6: 2026-04-14 | B6: Dr Ambedkar Jayanti / Tamil New Year | C6: LOC-BLR,LOC-PUN,LOC-CHN | D6: Festival
A7: 2026-05-01 | B7: May Day | C7: ALL | D7: Statutory
A8: 2026-08-15 | B8: Independence Day | C8: ALL | D8: National
A9: 2026-08-26 | B9: Ganesh Chaturthi | C9: LOC-BLR,LOC-PUN | D9: Festival
A10: 2026-09-15 | B10: Vinayaka Chaturthi | C10: LOC-HYD,LOC-CHN | D10: Festival
A11: 2026-10-02 | B11: Gandhi Jayanti | C11: ALL | D11: National
A12: 2026-10-20 | B12: Ayudha Puja / Dussehra | C12: LOC-BLR,LOC-CHN,LOC-HYD | D12: Festival
... A14: 2026-12-25 | B14: Christmas | C14: LOC-CHN | D14: Festival
A16: Holidays differ by location. 15 Sep 2026 is a holiday at Hyderabad and Chennai only, which is visible in the September attendance for E1056.

Sheet 10_Sanctioned_Manpower
A1: Record | B1: Org unit | C1: Designation | D1: Location | E1: Sanctioned | F1: Filled | G1: Open requisitions | H1: Effective from | I1: Approved by | J1: Demo point
A2: SM-001 | B2: OU-111 | C2: DES-13 | D2: LOC-PLA | E2: 24 | F2: 24 | G2: 1 | H2: 2026-04-01 | I2: E1002 | J2: Point 25
A3: SM-002 | B3: OU-111 | C3: DES-08 | D3: LOC-PLA | E3: 4 | F3: 3 | G3: 1 | H3: 2026-04-01 | I3: E1002 | J3: Point 24
A4: SM-003 | B4: OU-112 | C4: DES-12 | D4: LOC-PLA | E4: 12 | F4: 11 | G4: 0 | H4: 2026-04-01 | I4: E1002
A5: SM-004 | B5: OU-113 | C5: DES-11 | D5: LOC-PLA | E5: 6 | F5: 6 | G5: 0 | H5: 2026-04-01 | I5: E1002 | J5: Updated v1.1 — E1069 joined against this line, so Quality Officers at Peenya are now at sanction
A6: SM-005 | B6: OU-114 | C6: DES-14 | D6: LOC-PLA | E6: 8 | F6: 8 | G6: 0 | H6: 2026-04-01 | I6: E1002
A7: SM-006 | B7: OU-112 | C7: DES-13 | D7: LOC-PUN | E7: 18 | F7: 16 | G7: 2 | H7: 2026-04-01 | I7: E1002
A8: SM-007 | B8: OU-111 | C8: DES-08 | D8: LOC-PUN | E8: 3 | F8: 3 | G8: 0 | H8: 2026-04-01 | I8: E1002
A9: SM-008 | B9: OU-113 | C9: DES-09 | D9: LOC-HYD | E9: 5 | F9: 4 | G9: 0 | H9: 2026-04-01 | I9: E1002
A10: SM-009 | B10: OU-111 | C10: DES-13 | D10: LOC-CHN | E10: 20 | F10: 18 | G10: 1 | H10: 2026-04-01 | I10: E1002
A11: SM-010 | B11: OU-122 | C11: DES-11 | D11: LOC-PUN | E11: 3 | F11: 3 | G11: 0 | H11: 2026-04-01 | I11: E1002
A13: Machining operators at Peenya are at full sanctioned strength — this is what blocks the addition requisition REQ-2026-0041 in sheet 26. UPDATED v1.1: SM-004 shows 6 of 6 filled after E1069 joined; the open requisition against it is closed.

Sheet 11_Positions
A1: Position code | B1: Title | C1: Org unit | D1: Location | E1: Grade | F1: Cost centre | G1: Status | H1: Current incumbent | I1: Last incumbent | J1: Vacated on | K1: Demo point
A2: POS-2214 | B2: Senior Engineer — Machining | C2: OU-111 | D2: LOC-PLA | E2: B | F2: CC-2100 | G2: Vacant | I2: E1071 | J2: 2026-08-22 | K2: Point 24
A3: POS-2216 | B3: Senior Engineer — Machining | C3: OU-111 | D3: LOC-PLA | E3: B | F3: CC-2100 | G3: Filled | H3: E1018
A4: POS-2301 | B4: Officer — Quality | C4: OU-113 | D4: LOC-PLA | E4: A | F4: CC-2300 | G4: Filled | H4: E1023
A5: POS-2410 | B5: Technician — Maintenance | C5: OU-114 | D5: LOC-PLA | E5: A | F5: CC-2400 | G5: Filled | H5: E1026
A6: POS-3121 | B6: Officer — Stores | C6: OU-121 | D6: LOC-PLA | E6: A | F6: CC-3100 | G6: Filled | H6: E1037
A7: POS-2225 | B7: Operator — Assembly | C7: OU-112 | D7: LOC-PUN | E7: A | F7: CC-2200 | G7: Vacant | I7: E1072 | J7: 2026-09-02
A8: POS-2226 | B8: Operator — Assembly | C8: OU-112 | D8: LOC-PUN | E8: A | F8: CC-2200 | G8: Vacant | I8: E1073 | J8: 2026-08-11
A9: POS-4011 | B9: Engineer — Engineering | C9: OU-130 | D9: LOC-BLR | E9: B | F9: CC-4000 | G9: Filled | H9: E1065
A10: POS-3210 | B10: Officer — Logistics | C10: OU-122 | D10: LOC-PUN | E10: A | F10: CC-3200 | G10: Filled | H10: E1066
A11: POS-2115 | B11: Operator — Machining | C11: OU-111 | D11: LOC-CHN | E11: A | F11: CC-2100 | G11: Vacant | I11: E1074 | J11: 2026-07-30
A13: A position exists with or without a person in it. E1071 to E1074 are prior incumbents who have left and are not in the employee sheet — they exist only as vacancy history.

Sheet 12_Employees
A1: Employee code | B1: Full name | C1: Gender | D1: Date of birth | E1: Date of joining | F1: Entity | G1: Location | H1: Org unit | I1: Designation | J1: Band | K1: Worker class | L1: Shift group | M1: Default shift | N1: Manager code | O1: Manager name | P1: Payroll group | Q1: Vendor | R1: Status | S1: UAN (dummy) | T1: Bank a/c last 4 | U1: Demo point / note | V1: Employment category | W1: Employment sub-category | X1: Rest day applicable | Y1: Rest day pattern | Z1: Wage basis | AA1: OT eligible | AB1: OT eligibility basis | AC1: OT rate multiplier | AD1: Leave scheme | AE1: Leave band | AF1: Trainee type | AG1: COFF lapse days | AH1: EL eligibility from | AI1: Payroll processing location | AJ1: Attendance location | AK1: Continuous service years | AL1: Grade rank | AM1: Exempt from grace deduction | AN1: Gate pass hours per month | AO1: Gate pass count per month | AP1: ERP employee key | AQ1: Resolution note
A2: E1001 | B2: Arvind Raghunathan | C2: M | D2: 1968-03-12 | E2: 2012-04-02 | F2: LE-01 | G2: LOC-BLR | H2: OU-100 | I2: DES-01 | J2: E | K2: WC-PERM | L2: OFFICE8 | M2: SH-F | P2: HO | R2: Active | S2: UAN000100037037 | T2: XXXX7017 | V2: CAT-PERM — Permanent | X2: Y | Y2: Sunday weekly off | Z2: Monthly | AA2: Y | AB2: All days | AC2: 2 | AD2: LS-AGM | AE2: AGM_AND_ABOVE | AG2: 60 | AH2: Not applicable — annual credit on 1 January | AI2: LOC-BLR | AJ2: LOC-BLR | AK2: 14.45 | AL2: 100 | AM2: Y | AN2: 4 | AO2: 2 | AP2: VPI-1001
A3: E1002 | B3: Meenakshi Sundaram | C3: F | D3: 1972-09-04 | E3: 2014-07-01 | F3: LE-01 | G3: LOC-BLR | H3: OU-110 | I3: DES-02 | J3: E | K3: WC-PERM | L3: OFFICE8 | M3: SH-F | N3: E1001 | O3: Arvind Raghunathan | P3: HO | R3: Active | S3: UAN000100037074 | T3: XXXX7034 | V3: CAT-PERM — Permanent | X3: Y | Y3: Sunday weekly off | Z3: Monthly | AA3: Y | AB3: All days | AC3: 2 | AD3: LS-AGM | AE3: AGM_AND_ABOVE | AG3: 60 | AH3: Not applicable — annual credit on 1 January | AI3: LOC-BLR | AJ3: LOC-BLR | AK3: 12.21 | AL3: 90 | AM3: Y | AN3: 4 | AO3: 2 | AP3: VPI-1002
A4: E1003 | B4: Farhan Qureshi | C4: M | D4: 1974-01-28 | E4: 2015-11-16 | F4: LE-01 | G4: LOC-BLR | H4: OU-150 | I4: DES-02 | J4: E | K4: WC-PERM | L4: OFFICE8 | M4: SH-F | N4: E1001 | O4: Arvind Raghunathan | P4: HO | R4: Active | S4: UAN000100037111 | T4: XXXX7051 | V4: CAT-PERM — Permanent | X4: Y | Y4: Sunday weekly off | Z4: Monthly | AA4: Y | AB4: All days | AC4: 2 | AD4: LS-AGM | AE4: AGM_AND_ABOVE | AG4: 60 | AH4: Not applicable — annual credit on 1 January | AI4: LOC-BLR | AJ4: LOC-BLR | AK4: 10.83 | AL4: 90 | AM4: Y | AN4: 4 | AO4: 2 | AP4: VPI-1003
A5: E1004 | B5: Ritu Balachandran | C5: F | D5: 1976-06-19 | E5: 2016-02-01 | F5: LE-01 | G5: LOC-BLR | H5: OU-160 | I5: DES-03 | J5: D | K5: WC-PERM | L5: OFFICE8 | M5: SH-F | N5: E1001 | O5: Arvind Raghunathan | P5: HO | R5: Active | S5: UAN000100037148 | T5: XXXX7068 | V5: CAT-PERM — Permanent | X5: Y | Y5: Sunday weekly off | Z5: Monthly | AA5: Y | AB5: All days | AC5: 2 | AD5: LS-AGM | AE5: AGM_AND_ABOVE | AG5: 60 | AH5: Not applicable — annual credit on 1 January | AI5: LOC-BLR | AJ5: LOC-BLR | AK5: 10.62 | AL5: 80 | AM5: Y | AN5: 4 | AO5: 2 | AP5: VPI-1004
A6: E1005 | B6: Prakash Venugopal | C6: M | D6: 1975-11-07 | E6: 2013-09-09 | F6: LE-01 | G6: LOC-BLR | H6: OU-130 | I6: DES-03 | J6: D | K6: WC-PERM | L6: OFFICE8 | M6: SH-F | N6: E1002 | O6: Meenakshi Sundaram | P6: HO | R6: Active | S6: UAN000100037185 | T6: XXXX7085 | V6: CAT-PERM — Permanent | X6: Y | Y6: Sunday weekly off | Z6: Monthly | AA6: Y | AB6: All days | AC6: 2 | AD6: LS-AGM | AE6: AGM_AND_ABOVE | AG6: 60 | AH6: Not applicable — annual credit on 1 January | AI6: LOC-BLR | AJ6: LOC-BLR | AK6: 13.02 | AL6: 80 | AM6: Y | AN6: 4 | AO6: 2 | AP6: VPI-1005
A7: E1006 | B7: Anita Mathew | C7: F | D7: 1988-04-23 | E7: 2019-06-03 | F7: LE-01 | G7: LOC-BLR | H7: OU-160 | I7: DES-06 | J7: C | K7: WC-PERM | L7: OFFICE8 | M7: SH-F | N7: E1004 | O7: Ritu Balachandran | P7: HO | R7: Active | S7: UAN000100037222 | T7: XXXX7102 | U7: HR Ops demo persona | V7: CAT-PERM — Permanent | X7: Y | Y7: Sunday weekly off | Z7: Monthly | AA7: Y | AB7: All days | AC7: 2 | AD7: LS-STD | AE7: STANDARD | AG7: 60 | AH7: Eligible — six months completed before 2026 | AI7: LOC-BLR | AJ7: LOC-BLR | AK7: 7.29 | AL7: 55 | AM7: Y | AN7: 4 | AO7: 2 | AP7: VPI-1006
A8: E1007 | B8: Deepak Sarangi | C8: M | D8: 1987-12-02 | E8: 2018-08-20 | F8: LE-01 | G8: LOC-BLR | H8: OU-150 | I8: DES-07 | J8: C | K8: WC-PERM | L8: OFFICE8 | M8: SH-F | N8: E1003 | O8: Farhan Qureshi | P8: HO | R8: Active | S8: UAN000100037259 | T8: XXXX7119 | U8: Payroll demo persona | V8: CAT-PERM — Permanent | X8: Y | Y8: Sunday weekly off | Z8: Monthly | AA8: Y | AB8: All days | AC8: 2 | AD8: LS-STD | AE8: STANDARD | AG8: 60 | AH8: Eligible — six months completed before 2026 | AI8: LOC-BLR | AJ8: LOC-BLR | AK8: 8.07 | AL8: 50 | AM8: Y | AN8: 4 | AO8: 2 | AP8: VPI-1007
A9: E1008 | B9: Shalini Krishnamurthy | C9: F | D9: 1995-07-30 | E9: 2022-01-10 | F9: LE-01 | G9: LOC-BLR | H9: OU-160 | I9: DES-11 | J9: A | K9: WC-PERM | L9: OFFICE8 | M9: SH-F | N9: E1006 | O9: Anita Mathew | P9: HO | R9: Active | S9: UAN000100037296 | T9: XXXX7136 | V9: CAT-PERM — Permanent | X9: Y | Y9: Sunday weekly off | Z9: Monthly | AA9: Y | AB9: All days | AC9: 2 | AD9: LS-STD | AE9: STANDARD | AG9: 60 | AH9: Eligible — six months completed before 2026 | AI9: LOC-BLR | AJ9: LOC-BLR | AK9: 4.68 | AL9: 30 | AM9: N | AN9: 4 | AO9: 2 | AP9: VPI-1008
A10: E1009 | B10: Vikram Chauhan | C10: M | D10: 1990-02-14 | E10: 2020-03-02 | F10: LE-01 | G10: LOC-BLR | H10: OU-160 | I10: DES-10 | J10: B | K10: WC-PERM | L10: OFFICE8 | M10: SH-F | N10: E1004 | O10: Ritu Balachandran | P10: HO | R10: Active | S10: UAN000100037333 | T10: XXXX7153 | U10: Compliance owner | V10: CAT-PERM — Permanent | X10: Y | Y10: Sunday weekly off | Z10: Monthly | AA10: Y | AB10: All days | AC10: 2 | AD10: LS-STD | AE10: STANDARD | AG10: 60 | AH10: Eligible — six months completed before 2026 | AI10: LOC-BLR | AJ10: LOC-BLR | AK10: 6.54 | AL10: 34 | AM10: N | AN10: 4 | AO10: 2 | AP10: VPI-1009
A11: E1010 | B11: Nandita Bose | C11: F | D11: 1985-10-11 | E11: 2017-05-15 | F11: LE-01 | G11: LOC-BLR | H11: OU-150 | I11: DES-05 | J11: C | K11: WC-PERM | L11: OFFICE8 | M11: SH-F | N11: E1003 | O11: Farhan Qureshi | P11: HO | R11: Active | S11: UAN000100037370 | T11: XXXX7170 | V11: CAT-PERM — Permanent | X11: Y | Y11: Sunday weekly off | Z11: Monthly | AA11: Y | AB11: All days | AC11: 2 | AD11: LS-STD | AE11: STANDARD | AG11: 60 | AH11: Eligible — six months completed before 2026 | AI11: LOC-BLR | AJ11: LOC-BLR | AK11: 9.34 | AL11: 60 | AM11: Y | AN11: 4 | AO11: 2 | AP11: VPI-1010
A12: E1011 | B12: Rohit Agarwal | C12: M | D12: 1993-05-26 | E12: 2021-09-06 | F12: LE-01 | G12: LOC-BLR | H12: OU-150 | I12: DES-11 | J12: A | K12: WC-PERM | L12: OFFICE8 | M12: SH-F | N12: E1010 | O12: Nandita Bose | P12: HO | R12: Active | S12: UAN000100037407 | T12: XXXX7187 | V12: CAT-PERM — Permanent | X12: Y | Y12: Sunday weekly off | Z12: Monthly | AA12: Y | AB12: All days | AC12: 2 | AD12: LS-STD | AE12: STANDARD | AG12: 60 | AH12: Eligible — six months completed before 2026 | AI12: LOC-BLR | AJ12: LOC-BLR | AK12: 5.02 | AL12: 30 | AM12: N | AN12: 4 | AO12: 2 | AP12: VPI-1011
A13: E1012 | B13: Sameer Kulkarni | C13: M | D13: 1986-08-08 | E13: 2019-02-11 | F13: LE-01 | G13: LOC-BLR | H13: OU-170 | I13: DES-06 | J13: C | K13: WC-PERM | L13: OFFICE8 | M13: SH-F | N13: E1003 | O13: Farhan Qureshi | P13: HO | R13: Active | S13: UAN000100037444 | T13: XXXX7204 | V13: CAT-PERM — Permanent | X13: Y | Y13: Sunday weekly off | Z13: Monthly | AA13: Y | AB13: All days | AC13: 2 | AD13: LS-STD | AE13: STANDARD | AG13: 60 | AH13: Eligible — six months completed before 2026 | AI13: LOC-BLR | AJ13: LOC-BLR | AK13: 7.59 | AL13: 55 | AM13: Y | AN13: 4 | AO13: 2 | AP13: VPI-1012
A14: E1013 | B14: Tanvi Deshmukh | C14: F | D14: 1997-01-17 | E14: 2023-07-17 | F14: LE-01 | G14: LOC-BLR | H14: OU-170 | I14: DES-09 | J14: B | K14: WC-PERM | L14: OFFICE8 | M14: SH-F | N14: E1012 | O14: Sameer Kulkarni | P14: HO | R14: Active | S14: UAN000100037481 | T14: XXXX7221 | V14: CAT-PERM — Permanent | X14: Y | Y14: Sunday weekly off | Z14: Monthly | AA14: Y | AB14: All days | AC14: 2 | AD14: LS-STD | AE14: STANDARD | AG14: 60 | AH14: Eligible — six months completed before 2026 | AI14: LOC-BLR | AJ14: LOC-BLR | AK14: 3.16 | AL14: 35 | AM14: N | AN14: 4 | AO14: 2 | AP14: VPI-1013
A15: E1014 | B15: Harish Nambiar | C15: M | D15: 1983-03-05 | E15: 2018-04-02 | F15: LE-01 | G15: LOC-BLR | H15: OU-140 | I15: DES-05 | J15: C | K15: WC-PERM | L15: OFFICE8 | M15: SH-F | N15: E1001 | O15: Arvind Raghunathan | P15: HO | R15: Active | S15: UAN000100037518 | T15: XXXX7238 | V15: CAT-PERM — Permanent | X15: Y | Y15: Sunday weekly off | Z15: Monthly | AA15: Y | AB15: All days | AC15: 2 | AD15: LS-STD | AE15: STANDARD | AG15: 60 | AH15: Eligible — six months completed before 2026 | AI15: LOC-BLR | AJ15: LOC-BLR | AK15: 8.45 | AL15: 60 | AM15: Y | AN15: 4 | AO15: 2 | AP15: VPI-1014
A16: E1015 | B16: Pooja Trivedi | C16: F | D16: 1989-09-21 | E16: 2020-10-05 | F16: LE-01 | G16: LOC-BLR | H16: OU-140 | I16: DES-06 | J16: C | K16: WC-PERM | L16: OFFICE8 | M16: SH-F | N16: E1014 | O16: Harish Nambiar | P16: HO | R16: Active | S16: UAN000100037555 | T16: XXXX7255 | V16: CAT-PERM — Permanent | X16: Y | Y16: Sunday weekly off | Z16: Monthly | AA16: Y | AB16: All days | AC16: 2 | AD16: LS-STD | AE16: STANDARD | AG16: 60 | AH16: Eligible — six months completed before 2026 | AI16: LOC-BLR | AJ16: LOC-BLR | AK16: 5.94 | AL16: 55 | AM16: Y | AN16: 4 | AO16: 2 | AP16: VPI-1015
A17: E1016 | B17: Basavaraj Hiremath | C17: M | D17: 1973-07-14 | E17: 2014-01-06 | F17: LE-01 | G17: LOC-PLA | H17: OU-110 | I17: DES-03 | J17: D | K17: WC-PERM | L17: STAFF9 | M17: SH-E | N17: E1002 | O17: Meenakshi Sundaram | P17: PLANT-BLR | R17: Active | S17: UAN000100037592 | T17: XXXX7272 | V17: CAT-PERM — Permanent | X17: Y | Y17: Sunday weekly off | Z17: Monthly | AA17: Y | AB17: All days | AC17: 2 | AD17: LS-AGM | AE17: AGM_AND_ABOVE | AG17: 60 | AH17: Not applicable — annual credit on 1 January | AI17: LOC-PLA | AJ17: LOC-PLA | AK17: 12.69 | AL17: 80 | AM17: Y | AN17: 4 | AO17: 2 | AP17: VPI-1016
A18: E1017 | B18: Nikhil Iyer | C18: M | D18: 1984-05-09 | E18: 2017-08-21 | F18: LE-01 | G18: LOC-PLA | H18: OU-111 | I18: DES-05 | J18: C | K18: WC-PERM | L18: STAFF9 | M18: SH-E | N18: E1016 | O18: Basavaraj Hiremath | P18: PLANT-BLR | R18: Active | S18: UAN000100037629 | T18: XXXX7289 | V18: CAT-PERM — Permanent | X18: Y | Y18: Sunday weekly off | Z18: Monthly | AA18: Y | AB18: All days | AC18: 2 | AD18: LS-STD | AE18: STANDARD | AG18: 60 | AH18: Eligible — six months completed before 2026 | AI18: LOC-PLA | AJ18: LOC-PLA | AK18: 9.07 | AL18: 60 | AM18: Y | AN18: 4 | AO18: 2 | AP18: VPI-1017
A19: E1018 | B19: Ravi Kulkarni | C19: M | D19: 1991-11-23 | E19: 2019-11-04 | F19: LE-01 | G19: LOC-PLA | H19: OU-111 | I19: DES-08 | J19: B | K19: WC-PERM | L19: PLANT12 | M19: SH-A | N19: E1017 | O19: Nikhil Iyer | P19: PLANT-BLR | R19: Active | S19: UAN000100037666 | T19: XXXX7306 | U19: Point 1 — 19h20m cross-midnight day | V19: CAT-PERM — Permanent | X19: Y | Y19: Sunday weekly off | Z19: Monthly | AA19: Y | AB19: All days | AC19: 2 | AD19: LS-STD | AE19: STANDARD | AG19: 60 | AH19: Eligible — six months completed before 2026 | AI19: LOC-PLA | AJ19: LOC-PLA | AK19: 6.86 | AL19: 40 | AM19: N | AN19: 4 | AO19: 2 | AP19: VPI-1018
A20: E1019 | B20: Sneha Nair | C20: F | D20: 1994-02-06 | E20: 2021-06-14 | F20: LE-01 | G20: LOC-PLA | H20: OU-111 | I20: DES-09 | J20: B | K20: WC-PERM | L20: PLANT12 | M20: SH-A | N20: E1017 | O20: Nikhil Iyer | P20: PLANT-BLR | R20: Active | S20: UAN000100037703 | T20: XXXX7323 | U20: Point 12 — four late instances | V20: CAT-PERM — Permanent | X20: Y | Y20: Sunday weekly off | Z20: Monthly | AA20: Y | AB20: All days | AC20: 2 | AD20: LS-STD | AE20: STANDARD | AG20: 60 | AH20: Eligible — six months completed before 2026 | AI20: LOC-PLA | AJ20: LOC-PLA | AK20: 5.25 | AL20: 35 | AM20: N | AN20: 4 | AO20: 2 | AP20: VPI-1019
A21: E1020 | B21: Arjun Bhat | C21: M | D21: 1996-06-29 | E21: 2022-02-07 | F21: LE-01 | G21: LOC-PLA | H21: OU-112 | I21: DES-09 | J21: B | K21: WC-PERM | L21: PLANT12 | M21: SH-A | N21: E1021 | O21: Rekha Deshpande | P21: PLANT-BLR | R21: Active | S21: UAN000100037740 | T21: XXXX7340 | U21: Point 13 — punches into B shift | V21: CAT-PERM — Permanent | X21: Y | Y21: Sunday weekly off | Z21: Monthly | AA21: Y | AB21: All days | AC21: 2 | AD21: LS-STD | AE21: STANDARD | AG21: 60 | AH21: Eligible — six months completed before 2026 | AI21: LOC-PLA | AJ21: LOC-PLA | AK21: 4.6 | AL21: 35 | AM21: N | AN21: 4 | AO21: 2 | AP21: VPI-1020
A22: E1021 | B22: Rekha Deshpande | C22: F | D22: 1982-12-16 | E22: 2016-09-12 | F22: LE-01 | G22: LOC-PLA | H22: OU-112 | I22: DES-06 | J22: C | K22: WC-PERM | L22: STAFF9 | M22: SH-E | N22: E1016 | O22: Basavaraj Hiremath | P22: PLANT-BLR | R22: Active | S22: UAN000100037777 | T22: XXXX7357 | U22: Manager demo persona | V22: CAT-PERM — Permanent | X22: Y | Y22: Sunday weekly off | Z22: Monthly | AA22: Y | AB22: All days | AC22: 2 | AD22: LS-STD | AE22: STANDARD | AG22: 60 | AH22: Eligible — six months completed before 2026 | AI22: LOC-PLA | AJ22: LOC-PLA | AK22: 10.01 | AL22: 55 | AM22: Y | AN22: 4 | AO22: 2 | AP22: VPI-1021
A23: E1022 | B23: Mohan Joseph | C23: M | D23: 1992-08-03 | E23: 2020-07-01 | F23: LE-01 | G23: LOC-PLA | H23: OU-112 | I23: DES-12 | J23: A | K23: WC-PERM | L23: PLANT12 | M23: SH-A | N23: E1021 | O23: Rekha Deshpande | P23: PLANT-BLR | R23: Active | S23: UAN000100037814 | T23: XXXX7374 | U23: Points 12, 9 — half day, absent, special-terms loan | V23: CAT-PERM — Permanent | X23: Y | Y23: Sunday weekly off | Z23: Monthly | AA23: Y | AB23: All days | AC23: 2 | AD23: LS-STD | AE23: STANDARD | AG23: 60 | AH23: Eligible — six months completed before 2026 | AI23: LOC-PLA | AJ23: LOC-PLA | AK23: 6.21 | AL23: 25 | AM23: N | AN23: 4 | AO23: 2 | AP23: VPI-1022
A24: E1023 | B24: Kavya Venkatesh | C24: F | D24: 1995-04-18 | E24: 2021-03-15 | F24: LE-01 | G24: LOC-PLA | H24: OU-113 | I24: DES-11 | J24: A | K24: WC-PERM | L24: PLANT12 | M24: SH-A | N24: E1024 | O24: Srinivas Achar | P24: PLANT-BLR | R24: Active | S24: UAN000100037851 | T24: XXXX7391 | U24: Point 11 — gate pass 2 x 2h | V24: CAT-PERM — Permanent | X24: Y | Y24: Sunday weekly off | Z24: Monthly | AA24: Y | AB24: All days | AC24: 2 | AD24: LS-STD | AE24: STANDARD | AG24: 60 | AH24: Eligible — six months completed before 2026 | AI24: LOC-PLA | AJ24: LOC-PLA | AK24: 5.5 | AL24: 30 | AM24: N | AN24: 4 | AO24: 2 | AP24: VPI-1023
A25: E1024 | B25: Srinivas Achar | C25: M | D25: 1980-10-27 | E25: 2015-12-01 | F25: LE-01 | G25: LOC-PLA | H25: OU-113 | I25: DES-07 | J25: C | K25: WC-PERM | L25: STAFF9 | M25: SH-E | N25: E1016 | O25: Basavaraj Hiremath | P25: PLANT-BLR | R25: Active | S25: UAN000100037888 | T25: XXXX7408 | V25: CAT-PERM — Permanent | X25: Y | Y25: Sunday weekly off | Z25: Monthly | AA25: Y | AB25: All days | AC25: 2 | AD25: LS-STD | AE25: STANDARD | AG25: 60 | AH25: Eligible — six months completed before 2026 | AI25: LOC-PLA | AJ25: LOC-PLA | AK25: 10.79 | AL25: 50 | AM25: Y | AN25: 4 | AO25: 2 | AP25: VPI-1024
A26: E1025 | B26: Lakshmi Gowda | C26: F | D26: 1998-03-09 | E26: 2023-01-09 | F26: LE-01 | G26: LOC-PLA | H26: OU-111 | I26: DES-13 | J26: A | K26: WC-PERM | L26: PLANT12 | M26: SH-A | N26: E1017 | O26: Nikhil Iyer | P26: PLANT-BLR | R26: Active | S26: UAN000100037925 | T26: XXXX7425 | V26: CAT-PERM — Permanent | X26: Y | Y26: Sunday weekly off | Z26: Monthly | AA26: Y | AB26: All days | AC26: 2 | AD26: LS-STD | AE26: STANDARD | AG26: 60 | AH26: Eligible — six months completed before 2026 | AI26: LOC-PLA | AJ26: LOC-PLA | AK26: 3.68 | AL26: 20 | AM26: N | AN26: 4 | AO26: 2 | AP26: VPI-1025
A27: E1026 | B27: Manjunath Poojary | C27: M | D27: 1990-01-31 | E27: 2019-04-22 | F27: LE-01 | G27: LOC-PLA | H27: OU-114 | I27: DES-14 | J27: A | K27: WC-PERM | L27: PLANT12 | M27: SH-B | N27: E1027 | O27: Girish Deshpande | P27: PLANT-BLR | R27: Active | S27: UAN000100037962 | T27: XXXX7442 | U27: Night shift | V27: CAT-PERM — Permanent | X27: Y | Y27: Sunday weekly off | Z27: Monthly | AA27: Y | AB27: All days | AC27: 2 | AD27: LS-STD | AE27: STANDARD | AG27: 60 | AH27: Eligible — six months completed before 2026 | AI27: LOC-PLA | AJ27: LOC-PLA | AK27: 7.4 | AL27: 20 | AM27: N | AN27: 4 | AO27: 2 | AP27: VPI-1026
A28: E1027 | B28: Girish Deshpande | C28: M | D28: 1981-06-11 | E28: 2017-02-13 | F28: LE-01 | G28: LOC-PLA | H28: OU-114 | I28: DES-07 | J28: C | K28: WC-PERM | L28: STAFF9 | M28: SH-E | N28: E1016 | O28: Basavaraj Hiremath | P28: PLANT-BLR | R28: Active | S28: UAN000100037999 | T28: XXXX7459 | V28: CAT-PERM — Permanent | X28: Y | Y28: Sunday weekly off | Z28: Monthly | AA28: Y | AB28: All days | AC28: 2 | AD28: LS-STD | AE28: STANDARD | AG28: 60 | AH28: Eligible — six months completed before 2026 | AI28: LOC-PLA | AJ28: LOC-PLA | AK28: 9.59 | AL28: 50 | AM28: Y | AN28: 4 | AO28: 2 | AP28: VPI-1027
A29: E1028 | B29: Yashoda Rani | C29: F | D29: 1989-05-02 | E29: 2018-10-29 | F29: LE-01 | G29: LOC-PLA | H29: OU-112 | I29: DES-12 | J29: A | K29: WC-PERM | L29: PLANT12 | M29: SH-A | N29: E1021 | O29: Rekha Deshpande | P29: PLANT-BLR | R29: Active | S29: UAN000100038036 | T29: XXXX7476 | U29: Point 6 — comp-off nearing lapse | V29: CAT-PERM — Permanent | X29: Y | Y29: Sunday weekly off | Z29: Monthly | AA29: Y | AB29: All days | AC29: 2 | AD29: LS-STD | AE29: STANDARD | AG29: 60 | AH29: Eligible — six months completed before 2026 | AI29: LOC-PLA | AJ29: LOC-PLA | AK29: 7.88 | AL29: 25 | AM29: N | AN29: 4 | AO29: 2 | AP29: VPI-1028
A30: E1029 | B30: Prashant Salian | C30: M | D30: 2000-09-15 | E30: 2024-08-01 | F30: LE-01 | G30: LOC-PLA | H30: OU-111 | I30: DES-13 | J30: A | K30: WC-PERM | L30: PLANT12 | M30: SH-B | N30: E1017 | O30: Nikhil Iyer | P30: PLANT-BLR | R30: Active | S30: UAN000100038073 | T30: XXXX7493 | V30: CAT-PERM — Permanent | X30: Y | Y30: Sunday weekly off | Z30: Monthly | AA30: Y | AB30: All days | AC30: 2 | AD30: LS-STD | AE30: STANDARD | AG30: 60 | AH30: Eligible — six months completed before 2026 | AI30: LOC-PLA | AJ30: LOC-PLA | AK30: 2.12 | AL30: 20 | AM30: N | AN30: 4 | AO30: 2 | AP30: VPI-1029
A31: E1030 | B31: Chetan Bhandary | C31: M | D31: 2003-04-26 | E31: 2026-07-01 | F31: LE-01 | G31: LOC-PLA | H31: OU-111 | I31: DES-15 | J31: T | K31: WC-TRN | L31: STAFF9 | M31: SH-E | N31: E1017 | O31: Nikhil Iyer | P31: PLANT-BLR | R31: Active | S31: UAN000100038110 | T31: XXXX7510 | U31: Point 7 — GET, July joiner, 3 CL/SL | V31: CAT-TRN — Trainee | W31: SUB-TRN — Engineer trainee | X31: Y | Y31: Sunday weekly off | Z31: Monthly | AA31: Y | AB31: All days | AC31: 2 | AD31: LS-TRN | AE31: TRAINEE_GET | AF31: GET | AG31: 60 | AH31: Not applicable — scheme accrues no EL | AI31: LOC-PLA | AJ31: LOC-PLA | AK31: 0.21 | AL31: 15 | AM31: N | AN31: 4 | AO31: 2 | AP31: VPI-1030
A32: E1031 | B32: Divya Hegde | C32: F | D32: 2004-08-12 | E32: 2026-07-01 | F32: LE-01 | G32: LOC-PLA | H32: OU-113 | I32: DES-16 | J32: T | K32: WC-TRN | L32: STAFF9 | M32: SH-E | N32: E1024 | O32: Srinivas Achar | P32: PLANT-BLR | R32: Active | S32: UAN000100038147 | T32: XXXX7527 | U32: Point 7 — DET, July joiner, 3 CL/SL | V32: CAT-TRN — Trainee | W32: SUB-TRN — Engineer trainee | X32: Y | Y32: Sunday weekly off | Z32: Monthly | AA32: Y | AB32: All days | AC32: 2 | AD32: LS-TRN | AE32: TRAINEE_DET | AF32: DET | AG32: 60 | AH32: Not applicable — scheme accrues no EL | AI32: LOC-PLA | AJ32: LOC-PLA | AK32: 0.21 | AL32: 14 | AM32: N | AN32: 4 | AO32: 2 | AP32: VPI-1031
A33: E1032 | B33: Shivanna Muniyappa | C33: M | D33: 1987-02-20 | E33: 2025-04-01 | F33: LE-01 | G33: LOC-PLA | H33: OU-111 | I33: DES-18 | J33: H | K33: WC-CONT | L33: PLANT12 | M33: SH-A | N33: E1017 | O33: Nikhil Iyer | P33: PLANT-BLR | Q33: VN-02 | R33: Active | S33: UAN000100038184 | T33: XXXX7544 | U33: Point 2 — daily wage, no rest day | V33: CAT-CONT — Contractual | X33: N | Z33: Daily | AA33: Y | AB33: All days | AC33: 2 | AD33: LS-NONE | AE33: NOT_ELIGIBLE | AH33: Not applicable — scheme accrues no EL | AI33: LOC-PLA | AJ33: LOC-PLA | AK33: 1.46 | AL33: 5 | AM33: N | AP33: VPI-1032 | AQ33: no rest day — resolves at category level; not leave eligible
A34: E1033 | B34: Ratnamma Devaraju | C34: F | D34: 1990-11-05 | E34: 2025-06-15 | F34: LE-01 | G34: LOC-PLA | H34: OU-112 | I34: DES-18 | J34: H | K34: WC-CONT | L34: PLANT12 | M34: SH-A | N34: E1021 | O34: Rekha Deshpande | P34: PLANT-BLR | Q34: VN-02 | R34: Active | S34: UAN000100038221 | T34: XXXX7561 | U34: Point 2 — daily wage, works Sunday | V34: CAT-CONT — Contractual | X34: N | Z34: Daily | AA34: Y | AB34: All days | AC34: 2 | AD34: LS-NONE | AE34: NOT_ELIGIBLE | AH34: Not applicable — scheme accrues no EL | AI34: LOC-PLA | AJ34: LOC-PLA | AK34: 1.25 | AL34: 5 | AM34: N | AP34: VPI-1033 | AQ34: no rest day — resolves at category level; not leave eligible
A35: E1034 | B35: Imran Shaikh | C35: M | D35: 1993-07-08 | E35: 2025-02-10 | F35: LE-01 | G35: LOC-PLA | H35: OU-112 | I35: DES-13 | J35: A | K35: WC-3PE | L35: PLANT12 | M35: SH-A | N35: E1021 | O35: Rekha Deshpande | P35: PLANT-BLR | Q35: VN-01 | R35: Active | S35: UAN000100038258 | T35: XXXX7578 | U35: Points 3, 4 — 3P employee, has rest days, OT rest/holiday only | V35: CAT-3P — Third party | W35: SUB-EMP — Employee | X35: Y | Y35: Sunday weekly off | Z35: Monthly | AA35: Y | AB35: Rest days and holidays only | AC35: 2 | AD35: LS-NONE | AE35: NOT_ELIGIBLE | AH35: Not applicable — scheme accrues no EL | AI35: LOC-PLA | AJ35: LOC-PLA | AK35: 1.59 | AL35: 20 | AM35: N | AP35: VPI-1034 | AQ35: OT only on a rest day or holiday; not leave eligible
A36: E1035 | B36: Ashok Naik | C36: M | D36: 1991-12-19 | E36: 2025-03-01 | F36: LE-01 | G36: LOC-PLA | H36: OU-114 | I36: DES-14 | J36: A | K36: WC-3PE | L36: PLANT12 | M36: SH-A | N36: E1027 | O36: Girish Deshpande | P36: PLANT-BLR | Q36: VN-01 | R36: Active | S36: UAN000100038295 | T36: XXXX7595 | V36: CAT-3P — Third party | W36: SUB-EMP — Employee | X36: Y | Y36: Sunday weekly off | Z36: Monthly | AA36: Y | AB36: Rest days and holidays only | AC36: 2 | AD36: LS-NONE | AE36: NOT_ELIGIBLE | AH36: Not applicable — scheme accrues no EL | AI36: LOC-PLA | AJ36: LOC-PLA | AK36: 1.54 | AL36: 20 | AM36: N | AP36: VPI-1035 | AQ36: OT only on a rest day or holiday; not leave eligible
A37: E1036 | B37: Lakshmi Rao | C37: F | D37: 1994-06-03 | E37: 2025-05-20 | F37: LE-01 | G37: LOC-PLA | H37: OU-121 | I37: DES-17 | J37: H | K37: WC-3PH | L37: PLANT12 | M37: SH-A | N37: E1037 | O37: Venkatesh Murthy | P37: PLANT-BLR | Q37: VN-01 | R37: Active | S37: UAN000100038332 | T37: XXXX7612 | U37: Point 3 — helper, no rest days | V37: CAT-3P — Third party | W37: SUB-HLP — Helper | X37: N | Z37: Daily | AA37: Y | AB37: Rest days and holidays only | AC37: 2 | AD37: LS-NONE | AE37: NOT_ELIGIBLE | AH37: Not applicable — scheme accrues no EL | AI37: LOC-PLA | AJ37: LOC-PLA | AK37: 1.32 | AL37: 5 | AM37: N | AP37: VPI-1036 | AQ37: no rest day — resolves at sub-category (Helper) level; OT only on a rest day or holiday; not leave eligible
A38: E1037 | B38: Venkatesh Murthy | C38: M | D38: 1986-09-28 | E38: 2019-07-08 | F38: LE-01 | G38: LOC-PLA | H38: OU-121 | I38: DES-11 | J38: A | K38: WC-PERM | L38: STAFF9 | M38: SH-E | N38: E1016 | O38: Basavaraj Hiremath | P38: PLANT-BLR | R38: Active | S38: UAN000100038369 | T38: XXXX7629 | V38: CAT-PERM — Permanent | X38: Y | Y38: Sunday weekly off | Z38: Monthly | AA38: Y | AB38: All days | AC38: 2 | AD38: LS-STD | AE38: STANDARD | AG38: 60 | AH38: Eligible — six months completed before 2026 | AI38: LOC-PLA | AJ38: LOC-PLA | AK38: 7.19 | AL38: 30 | AM38: N | AN38: 4 | AO38: 2 | AP38: VPI-1037
A39: E1038 | B39: Parvathi Bai | C39: F | D39: 1996-01-22 | E39: 2026-01-12 | F39: LE-01 | G39: LOC-PLA | H39: OU-121 | I39: DES-17 | J39: H | K39: WC-3PH | L39: PLANT12 | M39: SH-A | N39: E1037 | O39: Venkatesh Murthy | P39: PLANT-BLR | Q39: VN-01 | R39: Active | S39: UAN000100038406 | T39: XXXX7646 | U39: Point 7 — January joiner reference | V39: CAT-3P — Third party | W39: SUB-HLP — Helper | X39: N | Z39: Daily | AA39: Y | AB39: Rest days and holidays only | AC39: 2 | AD39: LS-NONE | AE39: NOT_ELIGIBLE | AH39: Not applicable — scheme accrues no EL | AI39: LOC-PLA | AJ39: LOC-PLA | AK39: 0.67 | AL39: 5 | AM39: N | AP39: VPI-1038 | AQ39: no rest day — resolves at sub-category (Helper) level; OT only on a rest day or holiday; not leave eligible
A40: E1039 | B40: Sanjay Pawar | C40: M | D40: 1977-04-17 | E40: 2015-06-01 | F40: LE-01 | G40: LOC-PUN | H40: OU-110 | I40: DES-03 | J40: D | K40: WC-PERM | L40: STAFF9 | M40: SH-E | N40: E1002 | O40: Meenakshi Sundaram | P40: PLANT-PUN | R40: Active | S40: UAN000100038443 | T40: XXXX7663 | V40: CAT-PERM — Permanent | X40: Y | Y40: Sunday weekly off | Z40: Monthly | AA40: Y | AB40: All days | AC40: 2 | AD40: LS-AGM | AE40: AGM_AND_ABOVE | AG40: 60 | AH40: Not applicable — annual credit on 1 January | AI40: LOC-PUN | AJ40: LOC-PUN | AK40: 11.29 | AL40: 80 | AM40: Y | AN40: 4 | AO40: 2 | AP40: VPI-1039
...

Sheet 13_Salary_Structure
A1: Employee code | B1: Name | C1: Worker class | D1: Wage type | E1: Basic (INR) | F1: DA (INR) | G1: HRA (INR) | H1: Conveyance (INR) | I1: Special allowance (INR) | J1: Daily rate (INR) | K1: Monthly retainer (INR) | L1: Monthly gross (INR) | M1: Wage base — Basic+DA (INR) | N1: Excluded components (INR) | O1: Excluded as % of gross | P1: 50% floor add-back (INR) | Q1: Statutory wage base (INR)
A2: E1001 | B2: Arvind Raghunathan | C2: WC-PERM | D2: Monthly | E2: 182000 | F2: 21840 | G2: 72800 | H2: 1600 | I2: 50960 | L2: =IF($D2<>"Monthly","",SUM($E2:$I2)) -> 329200 | M2: =IF($D2<>"Monthly","",$E2+$F2) -> 203840 | N2: =IF($D2<>"Monthly","",$L2-$M2) -> 125360 | O2: =IF($D2<>"Monthly","",$N2/$L2) -> 0.38080194 | P2: =IF($D2<>"Monthly","",MAX(0,$N2-0.5*$L2)) -> 0 | Q2: =IF($D2<>"Monthly","",$M2+$P2) -> 203840
A3: E1002 | B3: Meenakshi Sundaram | C3: WC-PERM | D3: Monthly | E3: 182250 | F3: 21870 | G3: 72900 | H3: 1600 | I3: 51030 | L3: =IF($D3<>"Monthly","",SUM($E3:$I3)) -> 329650 | M3: =IF($D3<>"Monthly","",$E3+$F3) -> 204120 | N3: =IF($D3<>"Monthly","",$L3-$M3) -> 125530 | O3: =IF($D3<>"Monthly","",$N3/$L3) -> 0.38079782 | P3: =IF($D3<>"Monthly","",MAX(0,$N3-0.5*$L3)) -> 0 | Q3: =IF($D3<>"Monthly","",$M3+$P3) -> 204120
A4: E1003 | B4: Farhan Qureshi | C4: WC-PERM | D4: Monthly | E4: 182500 | F4: 21900 | G4: 73000 | H4: 1600 | I4: 51100 | L4: =IF($D4<>"Monthly","",SUM($E4:$I4)) -> 330100 | M4: =IF($D4<>"Monthly","",$E4+$F4) -> 204400 | N4: =IF($D4<>"Monthly","",$L4-$M4) -> 125700 | O4: =IF($D4<>"Monthly","",$N4/$L4) -> 0.3807937 | P4: =IF($D4<>"Monthly","",MAX(0,$N4-0.5*$L4)) -> 0 | Q4: =IF($D4<>"Monthly","",$M4+$P4) -> 204400
A5: E1004 | B5: Ritu Balachandran | C5: WC-PERM | D5: Monthly | E5: 108750 | F5: 13050 | G5: 43500 | H5: 1600 | I5: 30450 | L5: =IF($D5<>"Monthly","",SUM($E5:$I5)) -> 197350 | M5: =IF($D5<>"Monthly","",$E5+$F5) -> 121800 | N5: =IF($D5<>"Monthly","",$L5-$M5) -> 75550 | O5: =IF($D5<>"Monthly","",$N5/$L5) -> 0.3828224 | P5: =IF($D5<>"Monthly","",MAX(0,$N5-0.5*$L5)) -> 0 | Q5: =IF($D5<>"Monthly","",$M5+$P5) -> 121800
A6: E1005 | B6: Prakash Venugopal | C6: WC-PERM | D6: Monthly | E6: 109000 | F6: 13080 | G6: 43600 | H6: 1600 | I6: 30520 | L6: =IF($D6<>"Monthly","",SUM($E6:$I6)) -> 197800 | M6: =IF($D6<>"Monthly","",$E6+$F6) -> 122080 | N6: =IF($D6<>"Monthly","",$L6-$M6) -> 75720 | O6: =IF($D6<>"Monthly","",$N6/$L6) -> 0.38281092 | P6: =IF($D6<>"Monthly","",MAX(0,$N6-0.5*$L6)) -> 0 | Q6: =IF($D6<>"Monthly","",$M6+$P6) -> 122080
A7: E1006 | B7: Anita Mathew | C7: WC-PERM | D7: Monthly | E7: 62250 | F7: 7470 | G7: 24900 | H7: 1600 | I7: 17430 | L7: =IF($D7<>"Monthly","",SUM($E7:$I7)) -> 113650 | M7: =IF($D7<>"Monthly","",$E7+$F7) -> 69720 | N7: =IF($D7<>"Monthly","",$L7-$M7) -> 43930 | O7: =IF($D7<>"Monthly","",$N7/$L7) -> 0.38653762 | P7: =IF($D7<>"Monthly","",MAX(0,$N7-0.5*$L7)) -> 0 | Q7: =IF($D7<>"Monthly","",$M7+$P7) -> 69720
A8: E1007 | B8: Deepak Sarangi | C8: WC-PERM | D8: Monthly | E8: 62500 | F8: 7500 | G8: 25000 | H8: 1600 | I8: 17500 | L8: =IF($D8<>"Monthly","",SUM($E8:$I8)) -> 114100 | M8: =IF($D8<>"Monthly","",$E8+$F8) -> 70000 | N8: =IF($D8<>"Monthly","",$L8-$M8) -> 44100 | O8: =IF($D8<>"Monthly","",$N8/$L8) -> 0.38650307 | P8: =IF($D8<>"Monthly","",MAX(0,$N8-0.5*$L8)) -> 0 | Q8: =IF($D8<>"Monthly","",$M8+$P8) -> 70000
A9: E1008 | B9: Shalini Krishnamurthy | C9: WC-PERM | D9: Monthly | E9: 21500 | F9: 2580 | G9: 8600 | H9: 1600 | I9: 6020 | L9: =IF($D9<>"Monthly","",SUM($E9:$I9)) -> 40300 | M9: =IF($D9<>"Monthly","",$E9+$F9) -> 24080 | N9: =IF($D9<>"Monthly","",$L9-$M9) -> 16220 | O9: =IF($D9<>"Monthly","",$N9/$L9) -> 0.40248139 | P9: =IF($D9<>"Monthly","",MAX(0,$N9-0.5*$L9)) -> 0 | Q9: =IF($D9<>"Monthly","",$M9+$P9) -> 24080
A10: E1009 | B10: Vikram Chauhan | C10: WC-PERM | D10: Monthly | E10: 37750 | F10: 4530 | G10: 15100 | H10: 1600 | I10: 10570 | L10: =IF($D10<>"Monthly","",SUM($E10:$I10)) -> 69550 | M10: =IF($D10<>"Monthly","",$E10+$F10) -> 42280 | N10: =IF($D10<>"Monthly","",$L10-$M10) -> 27270 | O10: =IF($D10<>"Monthly","",$N10/$L10) -> 0.39209202 | P10: =IF($D10<>"Monthly","",MAX(0,$N10-0.5*$L10)) -> 0 | Q10: =IF($D10<>"Monthly","",$M10+$P10) -> 42280
A11: E1010 | B11: Nandita Bose | C11: WC-PERM | D11: Monthly | E11: 61500 | F11: 7380 | G11: 24600 | H11: 1600 | I11: 17220 | L11: =IF($D11<>"Monthly","",SUM($E11:$I11)) -> 112300 | M11: =IF($D11<>"Monthly","",$E11+$F11) -> 68880 | N11: =IF($D11<>"Monthly","",$L11-$M11) -> 43420 | O11: =IF($D11<>"Monthly","",$N11/$L11) -> 0.38664292 | P11: =IF($D11<>"Monthly","",MAX(0,$N11-0.5*$L11)) -> 0 | Q11: =IF($D11<>"Monthly","",$M11+$P11) -> 68880
A12: E1011 | B12: Rohit Agarwal | C12: WC-PERM | D12: Monthly | E12: 22250 | F12: 2670 | G12: 8900 | H12: 1600 | I12: 6230 | L12: =IF($D12<>"Monthly","",SUM($E12:$I12)) -> 41650 | M12: =IF($D12<>"Monthly","",$E12+$F12) -> 24920 | N12: =IF($D12<>"Monthly","",$L12-$M12) -> 16730 | O12: =IF($D12<>"Monthly","",$N12/$L12) -> 0.40168067 | P12: =IF($D12<>"Monthly","",MAX(0,$N12-0.5*$L12)) -> 0 | Q12: =IF($D12<>"Monthly","",$M12+$P12) -> 24920
